<robot name="onshape">
<link name="base_link">
<visual>
<origin xyz="0.070678574689464312986 -0.094010539903862488931 0.15232774369985618845" rpy="-2.2757746540218444231 -0.80896846272084954599 0.69616562304406370831" />
<geometry>
<mesh filename="/home/bjouvelot/ros2_ws/src/urchin_robot/urdf/base.stl"/>
</geometry>
<material name="base_material">
<color rgba="0.71764705882352941568 0.71764705882352941568 0.71764705882352941568 1.0"/>
</material>
</visual>
<collision>
<origin xyz="0.070678574689464312986 -0.094010539903862488931 0.15232774369985618845" rpy="-2.2757746540218444231 -0.80896846272084954599 0.69616562304406370831" />
<geometry>
<mesh filename="/home/bjouvelot/ros2_ws/src/urchin_robot/urdf/base.stl"/>
</geometry>
</collision>
<inertial>
<origin xyz="0.065224462017111753398 -0.095127354292411439585 0.17844842277483158322" rpy="0 0 0"/>
<mass value="13.910070322106195206" />
<inertia ixx="0.16187030661798218478" ixy="-6.4804601117627111824e-09"  ixz="9.835429739646217231e-09" iyy="0.16187026291327530347" iyz="-1.3005047689640839966e-08" izz="0.16187025347364486505" />
</inertial>
</link>

<link name="dummy_link">
  <inertial>
    <mass value="0.001"/>
    <inertia ixx="1e-6" ixy="0.0" ixz="0.0" iyy="1e-6" iyz="0.0" izz="1e-6"/>
  </inertial>
</link>
<joint name="base_to_dummy" type="fixed">
  <parent link="dummy_link"/>
  <child link="base_link"/>
</joint>

<link name="part_1">
<visual>
<origin xyz="6.9388939039072283776e-18 0 -0.047999999999999987121" rpy="2.6104898781181265598e-17 2.2035375562283580117e-17 -1.3507799912942693964e-17" />
<geometry>
<mesh filename="/home/bjouvelot/ros2_ws/src/urchin_robot/urdf/part_1.stl"/>
</geometry>
<material name="part_1_material">
<color rgba="0.32549019607843138191 0.52941176470588235947 0.75294117647058822484 1.0"/>
</material>
</visual>
<collision>
<origin xyz="6.9388939039072283776e-18 0 -0.047999999999999987121" rpy="2.6104898781181265598e-17 2.2035375562283580117e-17 -1.3507799912942693964e-17" />
<geometry>
<mesh filename="/home/bjouvelot/ros2_ws/src/urchin_robot/urdf/part_1.stl"/>
</geometry>
</collision>
<inertial>
<origin xyz="8.5422687912312918531e-18 3.2890382502089451937e-19 -0.023999999999999993561" rpy="0 0 0"/>
<mass value="0.090817631668871787176" />
<inertia ixx="2.83760257759587641e-05" ixy="-1.1553929499711443289e-21"  ixz="4.4633985156610295497e-22" iyy="2.8376025775958760712e-05" iyz="1.0405776357802651431e-21" izz="2.1878080991070783138e-05" />
</inertial>
</link>

<joint name="leg1" type="prismatic">
<origin xyz="0.026508289401707255117 -0.12224722702127144291 0.36476202517641048706" rpy="-0.017583829022371315343 -0.24785783489268173319 0.6826076112353128833" />
<parent link="base_link" />
<child link="part_1" />
<axis xyz="0 0 1"/>
<limit effort="1" velocity="20" lower="0" upper="0.16400000000000000688"/>
<joint_properties friction="0.0"/>
</joint>

<link name="part_1_2">
<visual>
<origin xyz="-4.1633363423443370266e-17 0 -0.047999999999999987121" rpy="7.3347634954558905603e-18 -1.0240992284846675533e-17 -2.2240244855271126446e-17" />
<geometry>
<mesh filename="/home/bjouvelot/ros2_ws/src/urchin_robot/urdf/part_1.stl"/>
</geometry>
<material name="part_1_material">
<color rgba="0.32549019607843138191 0.52941176470588235947 0.75294117647058822484 1.0"/>
</material>
</visual>
<collision>
<origin xyz="-4.1633363423443370266e-17 0 -0.047999999999999987121" rpy="7.3347634954558905603e-18 -1.0240992284846675533e-17 -2.2240244855271126446e-17" />
<geometry>
<mesh filename="/home/bjouvelot/ros2_ws/src/urchin_robot/urdf/part_1.stl"/>
</geometry>
</collision>
<inertial>
<origin xyz="-4.2104985051008619873e-17 -1.0585515204732326671e-19 -0.023999999999999986622" rpy="0 0 0"/>
<mass value="0.090817631668871787176" />
<inertia ixx="2.8376025775958770876e-05" ixy="1.0148065325143529983e-21"  ixz="-5.2932434448848571693e-22" iyy="2.8376025775958774264e-05" iyz="1.1163528843205737262e-22" izz="2.1878080991070789914e-05" />
</inertial>
</link>

<joint name="leg2" type="prismatic">
<origin xyz="-0.11793479394801316407 -0.072818533046672601072 0.23232038116063374877" rpy="-1.0591916489305985838 -0.96128431840861294777 1.018155300296469612" />
<parent link="base_link" />
<child link="part_1_2" />
<axis xyz="0 0 1"/>
<limit effort="1" velocity="20" lower="0" upper="0.16400000000000000688"/>
<joint_properties friction="0.0"/>
</joint>

<link name="part_1_3">
<visual>
<origin xyz="2.7755575615628913511e-17 -2.7755575615628913511e-17 -0.047999999999999987121" rpy="-1.1568393606084544768e-16 -3.4110663803636827147e-17 6.4135666057136817469e-17" />
<geometry>
<mesh filename="/home/bjouvelot/ros2_ws/src/urchin_robot/urdf/part_1.stl"/>
</geometry>
<material name="part_1_material">
<color rgba="0.32549019607843138191 0.52941176470588235947 0.75294117647058822484 1.0"/>
</material>
</visual>
<collision>
<origin xyz="2.7755575615628913511e-17 -2.7755575615628913511e-17 -0.047999999999999987121" rpy="-1.1568393606084544768e-16 -3.4110663803636827147e-17 6.4135666057136817469e-17" />
<geometry>
<mesh filename="/home/bjouvelot/ros2_ws/src/urchin_robot/urdf/part_1.stl"/>
</geometry>
</collision>
<inertial>
<origin xyz="2.8603647010256040199e-17 -2.8792513515850471483e-17 -0.023999999999999993561" rpy="0 0 0"/>
<mass value="0.090817631668871787176" />
<inertia ixx="2.8376025775958784429e-05" ixy="3.9539942367050756874e-21"  ixz="1.3510166874121952702e-21" iyy="2.8376025775958767488e-05" iyz="-4.2279091583501700116e-21" izz="2.1878080991070783138e-05" />
</inertial>
</link>

<joint name="leg3" type="prismatic">
<origin xyz="0.024455351418508061712 0.061911487980568856437 0.28152055507583295668" rpy="-0.90543761214525908532 -0.51840503634872225902 -0.11683492784473356596" />
<parent link="base_link" />
<child link="part_1_3" />
<axis xyz="0 0 1"/>
<limit effort="1" velocity="20" lower="0" upper="0.16400000000000000688"/>
<joint_properties friction="0.0"/>
</joint>

<link name="part_1_4">
<visual>
<origin xyz="0 0 -0.047999999999999987121" rpy="-2.7079008875253532336e-17 6.9869758018487935039e-17 9.2120863166359433376e-17" />
<geometry>
<mesh filename="/home/bjouvelot/ros2_ws/src/urchin_robot/urdf/part_1.stl"/>
</geometry>
<material name="part_1_material">
<color rgba="0.32549019607843138191 0.52941176470588235947 0.75294117647058822484 1.0"/>
</material>
</visual>
<collision>
<origin xyz="0 0 -0.047999999999999987121" rpy="-2.7079008875253532336e-17 6.9869758018487935039e-17 9.2120863166359433376e-17" />
<geometry>
<mesh filename="/home/bjouvelot/ros2_ws/src/urchin_robot/urdf/part_1.stl"/>
</geometry>
</collision>
<inertial>
<origin xyz="8.8815566295530127662e-19 1.4328070400133181693e-18 -0.023999999999999993561" rpy="0 0 0"/>
<mass value="0.090817631668871787176" />
<inertia ixx="2.8376025775958770876e-05" ixy="3.53854938208663851e-21"  ixz="-1.5629941562011647803e-21" iyy="2.8376025775958767488e-05" iyz="5.3773319891788009384e-22" izz="2.1878080991070783138e-05" />
</inertial>
</link>

<joint name="leg4" type="prismatic">
<origin xyz="0.19925909505640723718 -0.037141834351634872569 0.3034267131296768949" rpy="-0.78431363604154724634 0.40647699030544420795 -0.78523677827889248881" />
<parent link="base_link" />
<child link="part_1_4" />
<axis xyz="0 0 1"/>
<limit effort="1" velocity="20" lower="0" upper="0.16400000000000000688"/>
<joint_properties friction="0.0"/>
</joint>

<link name="part_1_5">
<visual>
<origin xyz="5.5511151231257827021e-17 -1.3877787807814456755e-17 -0.047999999999999987121" rpy="3.4746088843986403618e-17 -6.5383606489533330299e-18 2.1465904006134389142e-17" />
<geometry>
<mesh filename="/home/bjouvelot/ros2_ws/src/urchin_robot/urdf/part_1.stl"/>
</geometry>
<material name="part_1_material">
<color rgba="0.32549019607843138191 0.52941176470588235947 0.75294117647058822484 1.0"/>
</material>
</visual>
<collision>
<origin xyz="5.5511151231257827021e-17 -1.3877787807814456755e-17 -0.047999999999999987121" rpy="3.4746088843986403618e-17 -6.5383606489533330299e-18 2.1465904006134389142e-17" />
<geometry>
<mesh filename="/home/bjouvelot/ros2_ws/src/urchin_robot/urdf/part_1.stl"/>
</geometry>
</collision>
<inertial>
<origin xyz="5.3935018009136773863e-17 -1.2168982237340861239e-17 -0.023999999999999986622" rpy="0 0 0"/>
<mass value="0.090817631668871787176" />
<inertia ixx="2.8376025775958770876e-05" ixy="9.7099926168462703095e-24"  ixz="-1.6412484036136675534e-21" iyy="2.8376025775958787817e-05" iyz="2.5436803571846389017e-21" izz="2.1878080991070789914e-05" />
</inertial>
</link>

<joint name="leg5" type="prismatic">
<origin xyz="0.16490360449063132253 -0.23309017533363729502 0.26776528939239752081" rpy="-0.94109540514166556413 0.66155197716292246657 -2.0950267850514108225" />
<parent link="base_link" />
<child link="part_1_5" />
<axis xyz="0 0 1"/>
<limit effort="1" velocity="20" lower="0" upper="0.16400000000000000688"/>
<joint_properties friction="0.0"/>
</joint>

<link name="part_1_6">
<visual>
<origin xyz="0 0 -2.7755575615628913511e-17" rpy="-3.141592653589793116 -4.851736429199485133e-17 -1.1229146796635854684e-16" />
<geometry>
<mesh filename="/home/bjouvelot/ros2_ws/src/urchin_robot/urdf/part_1.stl"/>
</geometry>
<material name="part_1_material">
<color rgba="0.32549019607843138191 0.52941176470588235947 0.75294117647058822484 1.0"/>
</material>
</visual>
<collision>
<origin xyz="0 0 -2.7755575615628913511e-17" rpy="-3.141592653589793116 -4.851736429199485133e-17 -1.1229146796635854684e-16" />
<geometry>
<mesh filename="/home/bjouvelot/ros2_ws/src/urchin_robot/urdf/part_1.stl"/>
</geometry>
</collision>
<inertial>
<origin xyz="-1.123147514193445732e-18 1.7114066000690630132e-18 -0.024000000000000024786" rpy="0 0 0"/>
<mass value="0.090817631668871787176" />
<inertia ixx="2.8376025775958770876e-05" ixy="-5.4723691542851018485e-21"  ixz="2.7905753234088717294e-21" iyy="2.8376025775958774264e-05" iyz="-2.7495364761117242921e-22" izz="2.1878080991070783138e-05" />
</inertial>
</link>

<joint name="leg6" type="prismatic">
<origin xyz="0.10599352968109090889 -0.25216619085586144955 0.075376365654277327488" rpy="2.2361550429509544635 -0.51840503449474406583 -0.11683492952678870003" />
<parent link="base_link" />
<child link="part_1_6" />
<axis xyz="0 0 1"/>
<limit effort="1" velocity="20" lower="0" upper="0.16400000000000000688"/>
<joint_properties friction="0.0"/>
</joint>

<link name="part_1_7">
<visual>
<origin xyz="0 2.7755575615628913511e-17 -0.047999999999999987121" rpy="3.3606429572465610549e-18 1.7463037188443073652e-17 -8.4215491670696958503e-17" />
<geometry>
<mesh filename="/home/bjouvelot/ros2_ws/src/urchin_robot/urdf/part_1.stl"/>
</geometry>
<material name="part_1_material">
<color rgba="0.32549019607843138191 0.52941176470588235947 0.75294117647058822484 1.0"/>
</material>
</visual>
<collision>
<origin xyz="0 2.7755575615628913511e-17 -0.047999999999999987121" rpy="3.3606429572465610549e-18 1.7463037188443073652e-17 -8.4215491670696958503e-17" />
<geometry>
<mesh filename="/home/bjouvelot/ros2_ws/src/urchin_robot/urdf/part_1.stl"/>
</geometry>
</collision>
<inertial>
<origin xyz="8.0907315701850801654e-19 2.7920200919024353895e-17 -0.023999999999999986622" rpy="0 0 0"/>
<mass value="0.090817631668871787176" />
<inertia ixx="2.83760257759587641e-05" ixy="-6.9192642470528915272e-21"  ixz="-1.4799025633858605744e-22" iyy="2.8376025775958787817e-05" iyz="2.4543192954799951026e-22" izz="2.1878080991070789914e-05" />
</inertial>
</link>

<joint name="leg7" type="prismatic">
<origin xyz="0.24838367517854048616 -0.11743616984137039694 0.12457653971794713232" rpy="2.0824010049143084622 -0.96128431849131013021 1.0181553003088497089" />
<parent link="base_link" />
<child link="part_1_7" />
<axis xyz="0 0 1"/>
<limit effort="1" velocity="20" lower="0" upper="0.16400000000000000688"/>
<joint_properties friction="0.0"/>
</joint>

<link name="part_1_8">
<visual>
<origin xyz="-3.4694469519536141888e-17 0 -0.048000000000000000999" rpy="5.0570356502760449864e-17 -4.7961025865832585313e-17 6.8918852154617291672e-18" />
<geometry>
<mesh filename="/home/bjouvelot/ros2_ws/src/urchin_robot/urdf/part_1.stl"/>
</geometry>
<material name="part_1_material">
<color rgba="0.32549019607843138191 0.52941176470588235947 0.75294117647058822484 1.0"/>
</material>
</visual>
<collision>
<origin xyz="-3.4694469519536141888e-17 0 -0.048000000000000000999" rpy="5.0570356502760449864e-17 -4.7961025865832585313e-17 6.8918852154617291672e-18" />
<geometry>
<mesh filename="/home/bjouvelot/ros2_ws/src/urchin_robot/urdf/part_1.stl"/>
</geometry>
</collision>
<inertial>
<origin xyz="-3.6429358830726465449e-17 3.2036099390611462018e-19 -0.0240000000000000005" rpy="0 0 0"/>
<mass value="0.090817631668871787176" />
<inertia ixx="2.83760257759587641e-05" ixy="-3.2170690161585977318e-21"  ixz="-6.10557728314056685e-22" iyy="2.8376025775958767488e-05" iyz="1.7270225634158345251e-21" izz="2.1878080991070789914e-05" />
</inertial>
</link>

<joint name="leg8" type="prismatic">
<origin xyz="0.10394059182384561557 -0.06800747583084447434 -0.0078651042683742442008" rpy="3.1240088255147062668 -0.24785783452480220079 0.68260761195801744616" />
<parent link="base_link" />
<child link="part_1_8" />
<axis xyz="0 0 1"/>
<limit effort="1" velocity="20" lower="0" upper="0.16400000000000000688"/>
<joint_properties friction="0.0"/>
</joint>

<link name="part_1_9">
<visual>
<origin xyz="0 -1.3877787807814456755e-17 -0.048000000000000014877" rpy="-1.1788907973684903958e-16 -4.8401651329963865406e-18 5.4335176694030832376e-17" />
<geometry>
<mesh filename="/home/bjouvelot/ros2_ws/src/urchin_robot/urdf/part_1.stl"/>
</geometry>
<material name="part_1_material">
<color rgba="0.32549019607843138191 0.52941176470588235947 0.75294117647058822484 1.0"/>
</material>
</visual>
<collision>
<origin xyz="0 -1.3877787807814456755e-17 -0.048000000000000014877" rpy="-1.1788907973684903958e-16 -4.8401651329963865406e-18 5.4335176694030832376e-17" />
<geometry>
<mesh filename="/home/bjouvelot/ros2_ws/src/urchin_robot/urdf/part_1.stl"/>
</geometry>
</collision>
<inertial>
<origin xyz="1.1193385443755311228e-18 -1.3981115525762577487e-17 -0.024000000000000017847" rpy="0 0 0"/>
<mass value="0.090817631668871787176" />
<inertia ixx="2.8376025775958770876e-05" ixy="3.0033268177894907406e-21"  ixz="7.6771979067612413276e-22" iyy="2.8376025775958774264e-05" iyz="-3.4394157395623667951e-21" izz="2.1878080991070783138e-05" />
</inertial>
</link>

<joint name="leg9" type="prismatic">
<origin xyz="-0.03113299990317370744 -0.25513958769270339566 0.22381915933096049875" rpy="0.80830039745873960566 -1.222043892713764901 0.18952137038999158913" />
<parent link="base_link" />
<child link="part_1_9" />
<axis xyz="0 0 1"/>
<limit effort="1" velocity="20" lower="0" upper="0.16400000000000000688"/>
<joint_properties friction="0.0"/>
</joint>

<link name="part_1_10">
<visual>
<origin xyz="-5.5511151231257827021e-17 -6.9388939039072283776e-18 -0.048000000000000014877" rpy="-2.8858389638427886649e-17 -1.1155600016765979157e-17 -9.2709037217458984792e-17" />
<geometry>
<mesh filename="/home/bjouvelot/ros2_ws/src/urchin_robot/urdf/part_1.stl"/>
</geometry>
<material name="part_1_material">
<color rgba="0.32549019607843138191 0.52941176470588235947 0.75294117647058822484 1.0"/>
</material>
</visual>
<collision>
<origin xyz="-5.5511151231257827021e-17 -6.9388939039072283776e-18 -0.048000000000000014877" rpy="-2.8858389638427886649e-17 -1.1155600016765979157e-17 -9.2709037217458984792e-17" />
<geometry>
<mesh filename="/home/bjouvelot/ros2_ws/src/urchin_robot/urdf/part_1.stl"/>
</geometry>
</collision>
<inertial>
<origin xyz="-5.4595857216128732206e-17 -9.0708742516422750025e-18 -0.024000000000000017847" rpy="0 0 0"/>
<mass value="0.090817631668871787176" />
<inertia ixx="2.83760257759587641e-05" ixy="-2.3491684473907280275e-21"  ixz="7.6092245303109081265e-22" iyy="2.8376025775958774264e-05" iyz="-2.7623713548626324085e-21" izz="2.1878080991070783138e-05" />
</inertial>
</link>

<joint name="leg10" type="prismatic">
<origin xyz="-0.068810213801495129227 -0.15311286838223750473 0.053470207730745969443" rpy="2.5952474690108937594 -0.70598873880633161715 -1.9802604947068094265" />
<parent link="base_link" />
<child link="part_1_10" />
<axis xyz="0 0 1"/>
<limit effort="1" velocity="20" lower="0" upper="0.16400000000000000688"/>
<joint_properties friction="0.0"/>
</joint>

<link name="part_1_11">
<visual>
<origin xyz="0 0 -1.3877787807814456755e-17" rpy="3.141592653589793116 -4.4268701547136516849e-19 -1.2130233426354671654e-17" />
<geometry>
<mesh filename="/home/bjouvelot/ros2_ws/src/urchin_robot/urdf/part_1.stl"/>
</geometry>
<material name="part_1_material">
<color rgba="0.32549019607843138191 0.52941176470588235947 0.75294117647058822484 1.0"/>
</material>
</visual>
<collision>
<origin xyz="0 0 -1.3877787807814456755e-17" rpy="3.141592653589793116 -4.4268701547136516849e-19 -1.2130233426354671654e-17" />
<geometry>
<mesh filename="/home/bjouvelot/ros2_ws/src/urchin_robot/urdf/part_1.stl"/>
</geometry>
</collision>
<inertial>
<origin xyz="-4.1385380116766020295e-19 -1.0010760970274680691e-19 -0.024000000000000017847" rpy="0 0 0"/>
<mass value="0.090817631668871787176" />
<inertia ixx="2.8376025775958770876e-05" ixy="-1.5419505321241833325e-21"  ixz="7.7982432100453138392e-22" iyy="2.8376025775958767488e-05" iyz="-9.9800764228076253412e-22" izz="2.1878080991070789914e-05" />
</inertial>
</link>

<joint name="leg11" type="prismatic">
<origin xyz="0.16158188114658994516 0.064884884840638368253 0.13307776154029196669" rpy="-1.8168659431166009899 0.24969317546926392271 -0.60401040614402190521" />
<parent link="base_link" />
<child link="part_1_11" />
<axis xyz="0 0 1"/>
<limit effort="1" velocity="20" lower="0" upper="0.16400000000000000688"/>
<joint_properties friction="0.0"/>
</joint>

<link name="part_1_12">
<visual>
<origin xyz="-1.3877787807814456755e-17 0 -3.4694469519536141888e-18" rpy="-3.141592653589793116 2.1787460762826960852e-17 1.0164552874573241184e-17" />
<geometry>
<mesh filename="/home/bjouvelot/ros2_ws/src/urchin_robot/urdf/part_1.stl"/>
</geometry>
<material name="part_1_material">
<color rgba="0.32549019607843138191 0.52941176470588235947 0.75294117647058822484 1.0"/>
</material>
</visual>
<collision>
<origin xyz="-1.3877787807814456755e-17 0 -3.4694469519536141888e-18" rpy="-3.141592653589793116 2.1787460762826960852e-17 1.0164552874573241184e-17" />
<geometry>
<mesh filename="/home/bjouvelot/ros2_ws/src/urchin_robot/urdf/part_1.stl"/>
</geometry>
</collision>
<inertial>
<origin xyz="-1.2354971318678680214e-17 -2.8444482451844309574e-18 -0.0240000000000000005" rpy="0 0 0"/>
<mass value="0.090817631668871787176" />
<inertia ixx="2.8376025775958770876e-05" ixy="1.0683395275501557934e-21"  ixz="-1.6164218196999671651e-21" iyy="2.8376025775958774264e-05" iyz="3.2531330438136417953e-21" izz="2.1878080991070789914e-05" />
</inertial>
</link>

<joint name="leg12" type="prismatic">
<origin xyz="-0.034454723133345535602 0.042835472432037779988 0.089131631665532590203" rpy="2.2004972478443267647 0.6615519774591118729 -2.0950267852476551766" />
<parent link="base_link" />
<child link="part_1_12" />
<axis xyz="0 0 1"/>
<limit effort="1" velocity="20" lower="0" upper="0.16400000000000000688"/>
<joint_properties friction="0.0"/>
</joint>


</robot>
