<sdf version='1.11'>
  <model name='onshape'>
    <link name='base_link'>
      <inertial>
        <pose>0.065224462017111753 -0.09512735429241144 0.17844842277483161 0 0 0</pose>
        <mass>13.910070322106201</mass>
        <inertia>
          <ixx>0.16187030661798221</ixx>
          <ixy>-6.4804601117627112e-09</ixy>
          <ixz>9.8354297396462172e-09</ixz>
          <iyy>0.1618702629132753</iyy>
          <iyz>-1.300504768964084e-08</iyz>
          <izz>0.16187025347364489</izz>
        </inertia>
      </inertial>
      <collision name='base_collision'>
        <pose>0.070678574689464313 -0.094010539903862489 0.15232774369985619 -2.275774654021844 -0.80896846272084977 0.69616562304406371</pose>
        <geometry>
          <mesh>
            <scale>1 1 1</scale>
            <uri>/home/bjouvelot/ros2_ws/src/urchin_robot/urdf/base.stl</uri>
          </mesh>
        </geometry>
      </collision>
      <visual name='base_visual'>
        <pose>0.070678574689464313 -0.094010539903862489 0.15232774369985619 -2.275774654021844 -0.80896846272084977 0.69616562304406371</pose>
        <geometry>
          <mesh>
            <scale>1 1 1</scale>
            <uri>/home/bjouvelot/ros2_ws/src/urchin_robot/urdf/base.stl</uri>
          </mesh>
        </geometry>
        <material>
          <diffuse>0.897058845 0.897058845 0.897058845 1</diffuse>
          <ambient>0.897058845 0.897058845 0.897058845 1</ambient>
        </material>
      </visual>
    </link>
    <joint name='leg1' type='prismatic'>
      <pose relative_to='base_link'>0.026508289401707259 -0.1222472270212714 0.36476202517641049 -0.017583829022371305 -0.24785783489268187 0.68260761123531288</pose>
      <parent>base_link</parent>
      <child>part_1</child>
      <axis>
        <xyz>0 0 1</xyz>
        <limit>
          <lower>0</lower>
          <upper>0.16400000000000001</upper>
          <effort>1</effort>
          <velocity>20</velocity>
        </limit>
        <dynamics>
          <spring_reference>0</spring_reference>
          <spring_stiffness>0</spring_stiffness>
        </dynamics>
      </axis>
    </joint>
    <link name='part_1'>
      <pose relative_to='leg1'>0 0 0 0 0 0</pose>
      <inertial>
        <pose>8.5422687912312919e-18 3.2890382502089452e-19 -0.02399999999999999 0 0 0</pose>
        <mass>0.090817631668871787</mass>
        <inertia>
          <ixx>2.8376025775958761e-05</ixx>
          <ixy>-1.155392949971144e-21</ixy>
          <ixz>4.4633985156610295e-22</ixz>
          <iyy>2.8376025775958761e-05</iyy>
          <iyz>1.040577635780265e-21</iyz>
          <izz>2.187808099107078e-05</izz>
        </inertia>
      </inertial>
      <collision name='part_1_collision'>
        <pose>6.9388939039072284e-18 0 -0.047999999999999987 2.6104898781181269e-17 2.203537556228358e-17 -1.3507799912942689e-17</pose>
        <geometry>
          <mesh>
            <scale>1 1 1</scale>
            <uri>/home/bjouvelot/ros2_ws/src/urchin_robot/urdf/part_1.stl</uri>
          </mesh>
        </geometry>
      </collision>
      <visual name='part_1_visual'>
        <pose>6.9388939039072284e-18 0 -0.047999999999999987 2.6104898781181269e-17 2.203537556228358e-17 -1.3507799912942689e-17</pose>
        <geometry>
          <mesh>
            <scale>1 1 1</scale>
            <uri>/home/bjouvelot/ros2_ws/src/urchin_robot/urdf/part_1.stl</uri>
          </mesh>
        </geometry>
        <material>
          <diffuse>0.406862766 0.661764741 0.941176474 1</diffuse>
          <ambient>0.406862766 0.661764741 0.941176474 1</ambient>
        </material>
      </visual>
    </link>
    <joint name='leg10' type='prismatic'>
      <pose relative_to='base_link'>-0.068810213801495129 -0.1531128683822375 0.053470207730745969 2.5952474690108942 -0.70598873880633173 -1.9802604947068088</pose>
      <parent>base_link</parent>
      <child>part_1_10</child>
      <axis>
        <xyz>0 0 1</xyz>
        <limit>
          <lower>0</lower>
          <upper>0.16400000000000001</upper>
          <effort>1</effort>
          <velocity>20</velocity>
        </limit>
        <dynamics>
          <spring_reference>0</spring_reference>
          <spring_stiffness>0</spring_stiffness>
        </dynamics>
      </axis>
    </joint>
    <link name='part_1_10'>
      <pose relative_to='leg10'>0 0 0 0 0 0</pose>
      <inertial>
        <pose>-5.4595857216128732e-17 -9.070874251642275e-18 -0.024000000000000021 0 0 0</pose>
        <mass>0.090817631668871787</mass>
        <inertia>
          <ixx>2.8376025775958761e-05</ixx>
          <ixy>-2.349168447390728e-21</ixy>
          <ixz>7.6092245303109081e-22</ixz>
          <iyy>2.8376025775958771e-05</iyy>
          <iyz>-2.762371354862632e-21</iyz>
          <izz>2.187808099107078e-05</izz>
        </inertia>
      </inertial>
      <collision name='part_1_10_collision'>
        <pose>-5.5511151231257827e-17 -6.9388939039072284e-18 -0.048000000000000008 -2.8858389638427893e-17 -1.1155600016765981e-17 -9.2709037217458985e-17</pose>
        <geometry>
          <mesh>
            <scale>1 1 1</scale>
            <uri>/home/bjouvelot/ros2_ws/src/urchin_robot/urdf/part_1.stl</uri>
          </mesh>
        </geometry>
      </collision>
      <visual name='part_1_10_visual'>
        <pose>-5.5511151231257827e-17 -6.9388939039072284e-18 -0.048000000000000008 -2.8858389638427893e-17 -1.1155600016765981e-17 -9.2709037217458985e-17</pose>
        <geometry>
          <mesh>
            <scale>1 1 1</scale>
            <uri>/home/bjouvelot/ros2_ws/src/urchin_robot/urdf/part_1.stl</uri>
          </mesh>
        </geometry>
        <material>
          <diffuse>0.406862766 0.661764741 0.941176474 1</diffuse>
          <ambient>0.406862766 0.661764741 0.941176474 1</ambient>
        </material>
      </visual>
    </link>
    <joint name='leg11' type='prismatic'>
      <pose relative_to='base_link'>0.16158188114658989 0.064884884840638368 0.13307776154029199 -1.8168659431166008 0.24969317546926414 -0.60401040614402213</pose>
      <parent>base_link</parent>
      <child>part_1_11</child>
      <axis>
        <xyz>0 0 1</xyz>
        <limit>
          <lower>0</lower>
          <upper>0.16400000000000001</upper>
          <effort>1</effort>
          <velocity>20</velocity>
        </limit>
        <dynamics>
          <spring_reference>0</spring_reference>
          <spring_stiffness>0</spring_stiffness>
        </dynamics>
      </axis>
    </joint>
    <link name='part_1_11'>
      <pose relative_to='leg11'>0 0 0 0 0 0</pose>
      <inertial>
        <pose>-4.138538011676602e-19 -1.0010760970274679e-19 -0.024000000000000021 0 0 0</pose>
        <mass>0.090817631668871787</mass>
        <inertia>
          <ixx>2.8376025775958771e-05</ixx>
          <ixy>-1.541950532124183e-21</ixy>
          <ixz>7.7982432100453138e-22</ixz>
          <iyy>2.8376025775958771e-05</iyy>
          <iyz>-9.9800764228076253e-22</iyz>
          <izz>2.187808099107079e-05</izz>
        </inertia>
      </inertial>
      <collision name='part_1_11_collision'>
        <pose>0 0 -1.387778780781446e-17 3.1415926535897931 -4.4268701547136517e-19 -1.213023342635467e-17</pose>
        <geometry>
          <mesh>
            <scale>1 1 1</scale>
            <uri>/home/bjouvelot/ros2_ws/src/urchin_robot/urdf/part_1.stl</uri>
          </mesh>
        </geometry>
      </collision>
      <visual name='part_1_11_visual'>
        <pose>0 0 -1.387778780781446e-17 3.1415926535897931 -4.4268701547136517e-19 -1.213023342635467e-17</pose>
        <geometry>
          <mesh>
            <scale>1 1 1</scale>
            <uri>/home/bjouvelot/ros2_ws/src/urchin_robot/urdf/part_1.stl</uri>
          </mesh>
        </geometry>
        <material>
          <diffuse>0.406862766 0.661764741 0.941176474 1</diffuse>
          <ambient>0.406862766 0.661764741 0.941176474 1</ambient>
        </material>
      </visual>
    </link>
    <joint name='leg12' type='prismatic'>
      <pose relative_to='base_link'>-0.034454723133345543 0.04283547243203778 0.08913163166553259 2.2004972478443272 0.66155197745911187 -2.0950267852476552</pose>
      <parent>base_link</parent>
      <child>part_1_12</child>
      <axis>
        <xyz>0 0 1</xyz>
        <limit>
          <lower>0</lower>
          <upper>0.16400000000000001</upper>
          <effort>1</effort>
          <velocity>20</velocity>
        </limit>
        <dynamics>
          <spring_reference>0</spring_reference>
          <spring_stiffness>0</spring_stiffness>
        </dynamics>
      </axis>
    </joint>
    <link name='part_1_12'>
      <pose relative_to='leg12'>0 0 0 0 0 0</pose>
      <inertial>
        <pose>-1.235497131867868e-17 -2.844448245184431e-18 -0.024 0 0 0</pose>
        <mass>0.090817631668871787</mass>
        <inertia>
          <ixx>2.8376025775958771e-05</ixx>
          <ixy>1.068339527550156e-21</ixy>
          <ixz>-1.616421819699967e-21</ixz>
          <iyy>2.8376025775958771e-05</iyy>
          <iyz>3.2531330438136422e-21</iyz>
          <izz>2.187808099107079e-05</izz>
        </inertia>
      </inertial>
      <collision name='part_1_12_collision'>
        <pose>-1.387778780781446e-17 0 -3.4694469519536142e-18 -3.1415926535897931 2.1787460762826961e-17 1.016455287457324e-17</pose>
        <geometry>
          <mesh>
            <scale>1 1 1</scale>
            <uri>/home/bjouvelot/ros2_ws/src/urchin_robot/urdf/part_1.stl</uri>
          </mesh>
        </geometry>
      </collision>
      <visual name='part_1_12_visual'>
        <pose>-1.387778780781446e-17 0 -3.4694469519536142e-18 -3.1415926535897931 2.1787460762826961e-17 1.016455287457324e-17</pose>
        <geometry>
          <mesh>
            <scale>1 1 1</scale>
            <uri>/home/bjouvelot/ros2_ws/src/urchin_robot/urdf/part_1.stl</uri>
          </mesh>
        </geometry>
        <material>
          <diffuse>0.406862766 0.661764741 0.941176474 1</diffuse>
          <ambient>0.406862766 0.661764741 0.941176474 1</ambient>
        </material>
      </visual>
    </link>
    <joint name='leg2' type='prismatic'>
      <pose relative_to='base_link'>-0.11793479394801321 -0.072818533046672601 0.23232038116063369 -1.0591916489305988 -0.96128431840861317 1.0181553002964703</pose>
      <parent>base_link</parent>
      <child>part_1_2</child>
      <axis>
        <xyz>0 0 1</xyz>
        <limit>
          <lower>0</lower>
          <upper>0.16400000000000001</upper>
          <effort>1</effort>
          <velocity>20</velocity>
        </limit>
        <dynamics>
          <spring_reference>0</spring_reference>
          <spring_stiffness>0</spring_stiffness>
        </dynamics>
      </axis>
    </joint>
    <link name='part_1_2'>
      <pose relative_to='leg2'>0 0 0 0 0 0</pose>
      <inertial>
        <pose>-4.210498505100862e-17 -1.058551520473233e-19 -0.02399999999999999 0 0 0</pose>
        <mass>0.090817631668871787</mass>
        <inertia>
          <ixx>2.8376025775958771e-05</ixx>
          <ixy>1.014806532514353e-21</ixy>
          <ixz>-5.2932434448848572e-22</ixz>
          <iyy>2.8376025775958771e-05</iyy>
          <iyz>1.116352884320574e-22</iyz>
          <izz>2.187808099107079e-05</izz>
        </inertia>
      </inertial>
      <collision name='part_1_2_collision'>
        <pose>-4.163336342344337e-17 0 -0.047999999999999987 7.3347634954558906e-18 -1.024099228484668e-17 -2.224024485527113e-17</pose>
        <geometry>
          <mesh>
            <scale>1 1 1</scale>
            <uri>/home/bjouvelot/ros2_ws/src/urchin_robot/urdf/part_1.stl</uri>
          </mesh>
        </geometry>
      </collision>
      <visual name='part_1_2_visual'>
        <pose>-4.163336342344337e-17 0 -0.047999999999999987 7.3347634954558906e-18 -1.024099228484668e-17 -2.224024485527113e-17</pose>
        <geometry>
          <mesh>
            <scale>1 1 1</scale>
            <uri>/home/bjouvelot/ros2_ws/src/urchin_robot/urdf/part_1.stl</uri>
          </mesh>
        </geometry>
        <material>
          <diffuse>0.406862766 0.661764741 0.941176474 1</diffuse>
          <ambient>0.406862766 0.661764741 0.941176474 1</ambient>
        </material>
      </visual>
    </link>
    <joint name='leg3' type='prismatic'>
      <pose relative_to='base_link'>0.024455351418508062 0.061911487980568863 0.28152055507583301 -0.9054376121452592 -0.51840503634872226 -0.11683492784473354</pose>
      <parent>base_link</parent>
      <child>part_1_3</child>
      <axis>
        <xyz>0 0 1</xyz>
        <limit>
          <lower>0</lower>
          <upper>0.16400000000000001</upper>
          <effort>1</effort>
          <velocity>20</velocity>
        </limit>
        <dynamics>
          <spring_reference>0</spring_reference>
          <spring_stiffness>0</spring_stiffness>
        </dynamics>
      </axis>
    </joint>
    <link name='part_1_3'>
      <pose relative_to='leg3'>0 0 0 0 0 0</pose>
      <inertial>
        <pose>2.860364701025604e-17 -2.8792513515850471e-17 -0.02399999999999999 0 0 0</pose>
        <mass>0.090817631668871787</mass>
        <inertia>
          <ixx>2.8376025775958781e-05</ixx>
          <ixy>3.9539942367050757e-21</ixy>
          <ixz>1.3510166874121951e-21</ixz>
          <iyy>2.8376025775958771e-05</iyy>
          <iyz>-4.22790915835017e-21</iyz>
          <izz>2.187808099107078e-05</izz>
        </inertia>
      </inertial>
      <collision name='part_1_3_collision'>
        <pose>2.775557561562891e-17 -2.775557561562891e-17 -0.047999999999999987 -1.156839360608454e-16 -3.4110663803636827e-17 6.4135666057136817e-17</pose>
        <geometry>
          <mesh>
            <scale>1 1 1</scale>
            <uri>/home/bjouvelot/ros2_ws/src/urchin_robot/urdf/part_1.stl</uri>
          </mesh>
        </geometry>
      </collision>
      <visual name='part_1_3_visual'>
        <pose>2.775557561562891e-17 -2.775557561562891e-17 -0.047999999999999987 -1.156839360608454e-16 -3.4110663803636827e-17 6.4135666057136817e-17</pose>
        <geometry>
          <mesh>
            <scale>1 1 1</scale>
            <uri>/home/bjouvelot/ros2_ws/src/urchin_robot/urdf/part_1.stl</uri>
          </mesh>
        </geometry>
        <material>
          <diffuse>0.406862766 0.661764741 0.941176474 1</diffuse>
          <ambient>0.406862766 0.661764741 0.941176474 1</ambient>
        </material>
      </visual>
    </link>
    <joint name='leg4' type='prismatic'>
      <pose relative_to='base_link'>0.19925909505640721 -0.037141834351634873 0.30342671312967689 -0.78431363604154725 0.40647699030544449 -0.78523677827889249</pose>
      <parent>base_link</parent>
      <child>part_1_4</child>
      <axis>
        <xyz>0 0 1</xyz>
        <limit>
          <lower>0</lower>
          <upper>0.16400000000000001</upper>
          <effort>1</effort>
          <velocity>20</velocity>
        </limit>
        <dynamics>
          <spring_reference>0</spring_reference>
          <spring_stiffness>0</spring_stiffness>
        </dynamics>
      </axis>
    </joint>
    <link name='part_1_4'>
      <pose relative_to='leg4'>0 0 0 0 0 0</pose>
      <inertial>
        <pose>8.8815566295530128e-19 1.432807040013318e-18 -0.02399999999999999 0 0 0</pose>
        <mass>0.090817631668871787</mass>
        <inertia>
          <ixx>2.8376025775958771e-05</ixx>
          <ixy>3.5385493820866393e-21</ixy>
          <ixz>-1.562994156201165e-21</ixz>
          <iyy>2.8376025775958771e-05</iyy>
          <iyz>5.3773319891788009e-22</iyz>
          <izz>2.187808099107078e-05</izz>
        </inertia>
      </inertial>
      <collision name='part_1_4_collision'>
        <pose>0 0 -0.047999999999999987 -2.7079008875253529e-17 6.9869758018487935e-17 9.2120863166359433e-17</pose>
        <geometry>
          <mesh>
            <scale>1 1 1</scale>
            <uri>/home/bjouvelot/ros2_ws/src/urchin_robot/urdf/part_1.stl</uri>
          </mesh>
        </geometry>
      </collision>
      <visual name='part_1_4_visual'>
        <pose>0 0 -0.047999999999999987 -2.7079008875253529e-17 6.9869758018487935e-17 9.2120863166359433e-17</pose>
        <geometry>
          <mesh>
            <scale>1 1 1</scale>
            <uri>/home/bjouvelot/ros2_ws/src/urchin_robot/urdf/part_1.stl</uri>
          </mesh>
        </geometry>
        <material>
          <diffuse>0.406862766 0.661764741 0.941176474 1</diffuse>
          <ambient>0.406862766 0.661764741 0.941176474 1</ambient>
        </material>
      </visual>
    </link>
    <joint name='leg5' type='prismatic'>
      <pose relative_to='base_link'>0.16490360449063129 -0.2330901753336373 0.26776528939239752 -0.94109540514166534 0.66155197716292247 -2.0950267850514108</pose>
      <parent>base_link</parent>
      <child>part_1_5</child>
      <axis>
        <xyz>0 0 1</xyz>
        <limit>
          <lower>0</lower>
          <upper>0.16400000000000001</upper>
          <effort>1</effort>
          <velocity>20</velocity>
        </limit>
        <dynamics>
          <spring_reference>0</spring_reference>
          <spring_stiffness>0</spring_stiffness>
        </dynamics>
      </axis>
    </joint>
    <link name='part_1_5'>
      <pose relative_to='leg5'>0 0 0 0 0 0</pose>
      <inertial>
        <pose>5.3935018009136768e-17 -1.216898223734086e-17 -0.02399999999999999 0 0 0</pose>
        <mass>0.090817631668871787</mass>
        <inertia>
          <ixx>2.8376025775958771e-05</ixx>
          <ixy>9.7099926168462703e-24</ixy>
          <ixz>-1.6412484036136679e-21</ixz>
          <iyy>2.8376025775958791e-05</iyy>
          <iyz>2.5436803571846389e-21</iyz>
          <izz>2.187808099107079e-05</izz>
        </inertia>
      </inertial>
      <collision name='part_1_5_collision'>
        <pose>5.5511151231257827e-17 -1.387778780781446e-17 -0.047999999999999987 3.4746088843986397e-17 -6.538360648953333e-18 2.1465904006134389e-17</pose>
        <geometry>
          <mesh>
            <scale>1 1 1</scale>
            <uri>/home/bjouvelot/ros2_ws/src/urchin_robot/urdf/part_1.stl</uri>
          </mesh>
        </geometry>
      </collision>
      <visual name='part_1_5_visual'>
        <pose>5.5511151231257827e-17 -1.387778780781446e-17 -0.047999999999999987 3.4746088843986397e-17 -6.538360648953333e-18 2.1465904006134389e-17</pose>
        <geometry>
          <mesh>
            <scale>1 1 1</scale>
            <uri>/home/bjouvelot/ros2_ws/src/urchin_robot/urdf/part_1.stl</uri>
          </mesh>
        </geometry>
        <material>
          <diffuse>0.406862766 0.661764741 0.941176474 1</diffuse>
          <ambient>0.406862766 0.661764741 0.941176474 1</ambient>
        </material>
      </visual>
    </link>
    <joint name='leg6' type='prismatic'>
      <pose relative_to='base_link'>0.1059935296810909 -0.25216619085586139 0.075376365654277327 2.236155042950954 -0.51840503449474429 -0.11683492952678876</pose>
      <parent>base_link</parent>
      <child>part_1_6</child>
      <axis>
        <xyz>0 0 1</xyz>
        <limit>
          <lower>0</lower>
          <upper>0.16400000000000001</upper>
          <effort>1</effort>
          <velocity>20</velocity>
        </limit>
        <dynamics>
          <spring_reference>0</spring_reference>
          <spring_stiffness>0</spring_stiffness>
        </dynamics>
      </axis>
    </joint>
    <link name='part_1_6'>
      <pose relative_to='leg6'>0 0 0 0 0 0</pose>
      <inertial>
        <pose>-1.1231475141934459e-18 1.711406600069063e-18 -0.024000000000000021 0 0 0</pose>
        <mass>0.090817631668871787</mass>
        <inertia>
          <ixx>2.8376025775958771e-05</ixx>
          <ixy>-5.4723691542851018e-21</ixy>
          <ixz>2.7905753234088721e-21</ixz>
          <iyy>2.8376025775958771e-05</iyy>
          <iyz>-2.7495364761117238e-22</iyz>
          <izz>2.187808099107078e-05</izz>
        </inertia>
      </inertial>
      <collision name='part_1_6_collision'>
        <pose>0 0 -2.775557561562891e-17 -3.1415926535897931 -4.8517364291994851e-17 -1.122914679663585e-16</pose>
        <geometry>
          <mesh>
            <scale>1 1 1</scale>
            <uri>/home/bjouvelot/ros2_ws/src/urchin_robot/urdf/part_1.stl</uri>
          </mesh>
        </geometry>
      </collision>
      <visual name='part_1_6_visual'>
        <pose>0 0 -2.775557561562891e-17 -3.1415926535897931 -4.8517364291994851e-17 -1.122914679663585e-16</pose>
        <geometry>
          <mesh>
            <scale>1 1 1</scale>
            <uri>/home/bjouvelot/ros2_ws/src/urchin_robot/urdf/part_1.stl</uri>
          </mesh>
        </geometry>
        <material>
          <diffuse>0.406862766 0.661764741 0.941176474 1</diffuse>
          <ambient>0.406862766 0.661764741 0.941176474 1</ambient>
        </material>
      </visual>
    </link>
    <joint name='leg7' type='prismatic'>
      <pose relative_to='base_link'>0.24838367517854049 -0.1174361698413704 0.1245765397179471 2.082401004914308 -0.96128431849131057 1.018155300308849</pose>
      <parent>base_link</parent>
      <child>part_1_7</child>
      <axis>
        <xyz>0 0 1</xyz>
        <limit>
          <lower>0</lower>
          <upper>0.16400000000000001</upper>
          <effort>1</effort>
          <velocity>20</velocity>
        </limit>
        <dynamics>
          <spring_reference>0</spring_reference>
          <spring_stiffness>0</spring_stiffness>
        </dynamics>
      </axis>
    </joint>
    <link name='part_1_7'>
      <pose relative_to='leg7'>0 0 0 0 0 0</pose>
      <inertial>
        <pose>8.0907315701850802e-19 2.7920200919024348e-17 -0.02399999999999999 0 0 0</pose>
        <mass>0.090817631668871787</mass>
        <inertia>
          <ixx>2.8376025775958761e-05</ixx>
          <ixy>-6.9192642470528915e-21</ixy>
          <ixz>-1.479902563385861e-22</ixz>
          <iyy>2.8376025775958791e-05</iyy>
          <iyz>2.4543192954799951e-22</iyz>
          <izz>2.187808099107079e-05</izz>
        </inertia>
      </inertial>
      <collision name='part_1_7_collision'>
        <pose>0 2.775557561562891e-17 -0.047999999999999987 3.3606429572465611e-18 1.7463037188443071e-17 -8.4215491670696959e-17</pose>
        <geometry>
          <mesh>
            <scale>1 1 1</scale>
            <uri>/home/bjouvelot/ros2_ws/src/urchin_robot/urdf/part_1.stl</uri>
          </mesh>
        </geometry>
      </collision>
      <visual name='part_1_7_visual'>
        <pose>0 2.775557561562891e-17 -0.047999999999999987 3.3606429572465611e-18 1.7463037188443071e-17 -8.4215491670696959e-17</pose>
        <geometry>
          <mesh>
            <scale>1 1 1</scale>
            <uri>/home/bjouvelot/ros2_ws/src/urchin_robot/urdf/part_1.stl</uri>
          </mesh>
        </geometry>
        <material>
          <diffuse>0.406862766 0.661764741 0.941176474 1</diffuse>
          <ambient>0.406862766 0.661764741 0.941176474 1</ambient>
        </material>
      </visual>
    </link>
    <joint name='leg8' type='prismatic'>
      <pose relative_to='base_link'>0.1039405918238456 -0.068007475830844474 -0.0078651042683742442 3.1240088255147058 -0.24785783452480231 0.68260761195801711</pose>
      <parent>base_link</parent>
      <child>part_1_8</child>
      <axis>
        <xyz>0 0 1</xyz>
        <limit>
          <lower>0</lower>
          <upper>0.16400000000000001</upper>
          <effort>1</effort>
          <velocity>20</velocity>
        </limit>
        <dynamics>
          <spring_reference>0</spring_reference>
          <spring_stiffness>0</spring_stiffness>
        </dynamics>
      </axis>
    </joint>
    <link name='part_1_8'>
      <pose relative_to='leg8'>0 0 0 0 0 0</pose>
      <inertial>
        <pose>-3.6429358830726472e-17 3.2036099390611462e-19 -0.024 0 0 0</pose>
        <mass>0.090817631668871787</mass>
        <inertia>
          <ixx>2.8376025775958761e-05</ixx>
          <ixy>-3.2170690161585981e-21</ixy>
          <ixz>-6.1055772831405669e-22</ixz>
          <iyy>2.8376025775958771e-05</iyy>
          <iyz>1.7270225634158349e-21</iyz>
          <izz>2.187808099107079e-05</izz>
        </inertia>
      </inertial>
      <collision name='part_1_8_collision'>
        <pose>-3.4694469519536142e-17 0 -0.048000000000000001 5.057035650276045e-17 -4.7961025865832591e-17 6.8918852154617292e-18</pose>
        <geometry>
          <mesh>
            <scale>1 1 1</scale>
            <uri>/home/bjouvelot/ros2_ws/src/urchin_robot/urdf/part_1.stl</uri>
          </mesh>
        </geometry>
      </collision>
      <visual name='part_1_8_visual'>
        <pose>-3.4694469519536142e-17 0 -0.048000000000000001 5.057035650276045e-17 -4.7961025865832591e-17 6.8918852154617292e-18</pose>
        <geometry>
          <mesh>
            <scale>1 1 1</scale>
            <uri>/home/bjouvelot/ros2_ws/src/urchin_robot/urdf/part_1.stl</uri>
          </mesh>
        </geometry>
        <material>
          <diffuse>0.406862766 0.661764741 0.941176474 1</diffuse>
          <ambient>0.406862766 0.661764741 0.941176474 1</ambient>
        </material>
      </visual>
    </link>
    <joint name='leg9' type='prismatic'>
      <pose relative_to='base_link'>-0.031132999903173711 -0.2551395876927034 0.2238191593309605 0.80830039745873938 -1.2220438927137662 0.18952137038999212</pose>
      <parent>base_link</parent>
      <child>part_1_9</child>
      <axis>
        <xyz>0 0 1</xyz>
        <limit>
          <lower>0</lower>
          <upper>0.16400000000000001</upper>
          <effort>1</effort>
          <velocity>20</velocity>
        </limit>
        <dynamics>
          <spring_reference>0</spring_reference>
          <spring_stiffness>0</spring_stiffness>
        </dynamics>
      </axis>
    </joint>
    <link name='part_1_9'>
      <pose relative_to='leg9'>0 0 0 0 0 0</pose>
      <inertial>
        <pose>1.1193385443755309e-18 -1.3981115525762581e-17 -0.024000000000000021 0 0 0</pose>
        <mass>0.090817631668871787</mass>
        <inertia>
          <ixx>2.8376025775958771e-05</ixx>
          <ixy>3.0033268177894911e-21</ixy>
          <ixz>7.6771979067612413e-22</ixz>
          <iyy>2.8376025775958771e-05</iyy>
          <iyz>-3.4394157395623668e-21</iyz>
          <izz>2.187808099107078e-05</izz>
        </inertia>
      </inertial>
      <collision name='part_1_9_collision'>
        <pose>0 -1.387778780781446e-17 -0.048000000000000008 -1.1788907973684899e-16 -4.8401651329963873e-18 5.4335176694030832e-17</pose>
        <geometry>
          <mesh>
            <scale>1 1 1</scale>
            <uri>/home/bjouvelot/ros2_ws/src/urchin_robot/urdf/part_1.stl</uri>
          </mesh>
        </geometry>
      </collision>
      <visual name='part_1_9_visual'>
        <pose>0 -1.387778780781446e-17 -0.048000000000000008 -1.1788907973684899e-16 -4.8401651329963873e-18 5.4335176694030832e-17</pose>
        <geometry>
          <mesh>
            <scale>1 1 1</scale>
            <uri>/home/bjouvelot/ros2_ws/src/urchin_robot/urdf/part_1.stl</uri>
          </mesh>
        </geometry>
        <material>
          <diffuse>0.406862766 0.661764741 0.941176474 1</diffuse>
          <ambient>0.406862766 0.661764741 0.941176474 1</ambient>
        </material>
      </visual>
    </link>
  </model>
</sdf>
